Workbook

Sheet Chronogramme
B2: Etat | C2: N° | D2: Type de stimuli | E2: Personnage | F2: Destinataire | G2: Objet | H2: Corps | I2: Modalité
B3: Tango 1 - biomed attaqué CHU et CHOR + problèmes réseau CHU
B4: ✅ | C4: T1-1 | D4: Structurant | E4: Chef de service cardiologie | F4: CCD CHU | G4: ="Panne "&Applicatifs!$B$6&" (Laboratoire)" -> Panne INLOG (Laboratoire) | H4: ="Bonjour, il semblerait qu'il y ait une panne au niveau du laboratoire de biologie. "&Applicatifs!$B$6&" est en panne. On doit se déplacer pour avoir les résultats, c'est très long et on a beaucoup de mal à tenir le rythme." -> Bonjour, il semblerait qu'il y ait une panne au niveau du laboratoire de biologie. INLOG est en panne. On doit se déplacer pour avoir les résultats, c'est très long et on a beaucoup de mal à tenir le rythme. | I4: Appel
B5: ✅ | C5: T1-2 | D5: Structurant | E5: Responsable imagerie | F5: CCD CHU | G5: Ralentissement PACS | H5: Bonjour, je vous appelle parce qu'il semblerait qu'il y ait un ralentissement du PACS. On a de plus en plus de mal à pouvoir consulter les résultats d'imagerie, c'est vraiment contraignant. A ce rythme là, on devra bientôt se déplacer pour les consulter directement sur les appareils d'imagerie. On perd un temps fou ! | I5: Appel
B6: ✅ | C6: T1-3 | D6: Structurant | E6: Infirmière | F6: CCD CHOR | G6: Panne Laboratoire | H6: ="Bonjour, il semblerait qu'il y ait une panne au niveau du laboratoire de biologie. On doit se déplacer pour avoir les résultats, c'est très long et on a beaucoup de mal à tenir le rythme." -> Bonjour, il semblerait qu'il y ait une panne au niveau du laboratoire de biologie. On doit se déplacer pour avoir les résultats, c'est très long et on a beaucoup de mal à tenir le rythme. | I6: Appel
B7: ✅ | C7: T1-4 | D7: Structurant | E7: Accueil | F7: CCD CHU | G7: Pop up Windows suspectes | H7: Bonjour, on arrête pas d'avoir des fenêtres qui s'ouvrent sans arrêt sur les postes avec des messages en anglais étranges. On dirait que l'ordinateur est hanté !! | I7: Appel
B8: ✅ | C8: T1-5 | D8: Structurant | E8: Cadre de santé | F8: CCD CHU | G8: Pop up Windows suspectes | H8: Bonjour, on arrête pas d'avoir des fenêtres qui s'ouvrent sans arrêt sur les postes avec des messages en anglais étranges. On dirait que l'ordinateur est hanté !! | I8: Appel
B9: ✅ | C9: T1-6 | D9: Structurant | E9: Responsable RH | F9: CCD CHU | G9: Pop up Windows suspectes | H9: Bonjour, on arrête pas d'avoir des fenêtres qui s'ouvrent sans arrêt sur les postes avec des messages en anglais étranges. On dirait que l'ordinateur est hanté !! | I9: Appel
B10: ✅ | C10: T1-7 | D10: Structurant | E10: Technicien informatique | F10: CCD CHU | G10: Pop up Windows suspectes | H10: Bonjour, j'ai constaté que des messages de service Windows suspects s'affichent sur les écrans de nombreux postes dans les services. | I10: Appel
B11: ✅ | C11: T1-8 | D11: Structurant | E11: Responsable imagerie | F11: CCOPS CHOR | G11: Ralentissement PACS | H11: Bonjour, je vous appelle parce qu'il semblerait qu'il y ait un ralentissement du PACS. On a de plus en plus de mal à pouvoir consulter les résultats d'imagerie, c'est vraiment contraignant. A ce rythme là, on devra bientôt se déplacer pour les consulter directement sur les appareils d'imagerie. On perd un temps fou ! | I11: Appel
B12: ✅ | C12: T1-9 | D12: Structurant | E12: ADVENS (PRIS) | F12: CCOPS CHU | G12: Le SOC EDR (opéré par ADVENS en métropole) remonte des alertes au CHU | H12: Objet : EXERCICE EXERCICE EXERCICE - Alerte SOC EDR - Activité suspecte détectée Bonjour, L'EDR a détecté une activité suspecte sur plusieurs systèmes. Il semble qu'un processus Windows légitime ait été lancé et ait établi des connexions réseau avec une adresse IP externe. Nous poursuivons les investigations. Cordialement, ADVENS | I12: E-mail
B13: ✅ | C13: T1-10 | D13: Saturant | E13: Service juridique | F13: CCD CHU | G13: Fichier qui ne s'ouvre pas au service juridique | H13: Bonsoir, j'ai besoin d'accéder à mon rapport d'investigation de la semaine dernière, mais sa lecture est impossible depuis mon PC. Le Procureur donne suite au dépôt de plainte d'une interne en cardiologie et j'ai besoin d'y accéder d'ici demain matin. | I13: Appel
B14: ✅ | C14: T1-11 | D14: Structurant | E14: Chef de service des urgences | F14: CCOPS CHU | G14: Ralentissements postes de travail | H14: Bonjour, les PC sont de plus en plus lents. On essaie de les redémarrer mais c'est vraiment laborieux. Que se passe-t-il ? | I14: Appel
B15: ✅ | C15: T1-12 | D15: Structurant | E15: Médecin | F15: CCOPS CHOR | G15: Perte accès au PACS | H15: Bonjour, Je vous appelle parce que nous n'arrivons plus à accéder aux images du PACS. Impossible d'accéder à l'historique des images du dossier, ça charge en boucle… | I15: Appel
B16: ✅ | C16: T1-13 | D16: Structurant | E16: Médecin | F16: CCOPS CHU | G16: Perte accès au PACS | H16: Bonjour, Je vous appelle parce que nous n'arrivons plus à accéder aux images du PACS. Impossible d'accéder à l'historique des images du dossier, ça charge en boucle… | I16: Appel
B17: ✅ | C17: T1-14 | D17: Structurant | E17: Cadre de santé | F17: CCD CHU | G17: Perte accès calendrier Outlook | H17: Bonjour, j'ai essayé d'accéder au calendrier Outlook mais impossible de le consulter. Même problème sur les différents PC du service, comment peut-on y accéder ? | I17: Appel
B18: ✅ | C18: T1-15 | D18: Structurant | E18: Responsable laboratoire | F18: CCD CHU | G18: Robot du laboratoire en panne | H18: Bonjour, on a une panne au niveau des laboratoires de biologie. Les étiquettes ne sortent pas, nous sommes passés en mode dégradé. Nous prenons du retard, nous tentons tout de même de transmettre les résultats les plus urgents | I18: E-mail
B19: ✅ | C19: T1-16 | D19: Structurant | E19: Responsable laboratoire | F19: CCD CHOR | G19: Robot du laboratoire en panne | H19: Bonjour, on a une panne au niveau des laboratoires de biologie. Les étiquettes ne sortent pas, nous sommes passés en mode dégradé. Nous prenons du retard, nous tentons tout de même de transmettre les résultats les plus urgents | I19: E-mail
B20: ✅ | C20: T1-17 | D20: Structurant | E20: Secrétaire médicale | F20: CCOPS CHU | G20: ="Bug de "&Applicatifs!$B$12&" (Gestion des plannings)" -> Bug de Logiciel de gestion des plannings (Gestion des plannings) | H20: ="Bonjour, c'est X qui vous contacte, on m'a informé qu'en plus de "&Applicatifs!$B$5&" il y a un bug sur "&Applicatifs!$B$12&". On n'a plus aucune visibilité sur les plannings, il y a une page blanche qui s'affiche sans aucun contenu, est-ce que c'est normal ?" -> Bonjour, c'est X qui vous contacte, on m'a informé qu'en plus de Pastel il y a un bug sur Logiciel de gestion des plannings. On n'a plus aucune visibilité sur les plannings, il y a une page blanche qui s'affiche sans aucun contenu, est-ce que c'est normal ? | I20: Appel
B21: ✅ | C21: T1-18 | D21: Structurant | E21: Chef de service réanimation | F21: CCD CHU | G21: Perte du monitoring | H21: Bonjour, je viens de m'apercevoir que les paramètres vitaux de nos patients sont figés sur l'écran de la salle de monitoring depuis un quart d'heure. On est obligés d'aller de chambre en chambre pour les surveiller. Est-ce qu'un technicien peut intervenir en urgence s'il vous plait ? | I21: Appel
B22: ✅ | C22: T1-19 | D22: Saturant | E22: Responsable maternité | F22: CCOPS CHU | G22: Fichier qui ne s'ouvre pas en maternité | H22: Bonsoir, j'essaye d'ouvrir un fichier excel depuis mon poste, mais mon PC m'indique que je ne peux pas l'ouvrir. Tout marchait pourtant très bien la dernière fois que je l'ai ouvert. Est-ce que vous pouvez me réinstaller Excel sur le PC ? | I22: Appel
B23: ✅ | C23: T1-20 | D23: Structurant | E23: Responsable laboratoire | F23: CCD CHU | G23: ="Bug de "&Applicatifs!$B$15&" (Gestion de la température)" -> Bug de Logiciel de gestion de la température (Laboratoire) (Gestion de la température) | H23: Bonjour, on est très inquiet au laboratoire, on vient de voir que le logiciel de gestion de la température ne fonctionnait pas cette nuit. La direction des services technique n'arrive pas a identifier le problème et on a aucun moyen de savoir si les frigos ont été maintenus à la bonne température. Ça pose un gros problème pour les poches sanguines, on ne sait pas quoi faire là. | I23: Appel
B24: ✅ | C24: T1-21 | D24: Structurant | E24: Responsable pharmacie | F24: CCOPS CHU | G24: ="Problème "&Applicatifs!$B$13&" (Gestion des stocks)" -> Problème Pharma® (Gestion des stocks) | H24: ="Bonjour, on vous contacte car depuis ce matin "&Applicatifs!$B$13&" est très lent depuis ce matin... Cela pèse sur le fonctionnement de la pharmacie car on tourne au ralenti. Savez-vous ce qu'il en est ?" -> Bonjour, on vous contacte car depuis ce matin Pharma® est très lent depuis ce matin... Cela pèse sur le fonctionnement de la pharmacie car on tourne au ralenti. Savez-vous ce qu'il en est ? | I24: Appel
B25: ✅ | C25: T1-22 | D25: Structurant | E25: Responsable laboratoire | F25: CCD CHOR | G25: ="Bug de "&Applicatifs!$B$15&" (Gestion de la température)" -> Bug de Logiciel de gestion de la température (Laboratoire) (Gestion de la température) | H25: Bonjour, on est très inquiet au laboratoire, on vient de voir que le logiciel de gestion de la température ne fonctionnait pas cette nuit. La direction des services technique n'arrive pas a identifier le problème et on a aucun moyen de savoir si les frigos ont été maintenus à la bonne température. Ça pose un gros problème pour les poches sanguines, on ne sait pas quoi faire là. | I25: Appel
B26: ✅ | C26: T1-23 | D26: Structurant | E26: Responsable pharmacie | F26: CCOPS CHOR | G26: ="Problème "&Applicatifs!$B$13&" (Gestion des stocks)" -> Problème Pharma® (Gestion des stocks) | H26: ="Bonjour, on vous contacte car depuis ce matin "&Applicatifs!$B$13&" est très lent depuis ce matin... Cela pèse sur le fonctionnement de la pharmacie car on tourne au ralenti. Savez-vous ce qu'il en est ?" -> Bonjour, on vous contacte car depuis ce matin Pharma® est très lent depuis ce matin... Cela pèse sur le fonctionnement de la pharmacie car on tourne au ralenti. Savez-vous ce qu'il en est ? | I26: Appel
B27: ✅ | C27: T1-24 | D27: Saturant | E27: Secrétaire médicale | F27: CCOPS CHU | G27: Les postes informatiques des admissions ne répondent plus | H27: Bonjour, je vous contacte en urgence car la GAM ne répond plus sur tous les postes informatiques au niveau du guichet des admissions aux urgences. Nous continuons de traiter les demandes en manuscrit mais ça ne va pas être possible indéfiniment, ça prend beaucoup de temps et nous sommes de plus en plus saturés. | I27: Appel
B28: ✅ | C28: T1-25 | D28: Structurant | E28: Prestataire biomédical - BioCom | F28: CC Biomédicale CHU Sud | G28: Alerte compromission SI prestataire biomédical | H28: Bonjour, Nous vous contactons car nous avons constaté des potentiels accès suspects à des données de nos comptes clients en date du 6 janvier. Nos équipes sont pleinement mobilisées sur les investigations. Pour l'heure nous n'avons pas de raison de penser que des accès de maintenance aient pu être compromis. Néanmoins dans un souci de transparence, nous souhaitions vous tenir informés de cette situation et nous vous tiendrons au courant des résultats de nos investigations. | I28: E-mail
B29: ✅ | C29: T1-26 | D29: Structurant | E29: Prestataire biomédical - BioCom | F29: CCOPS CHOR | G29: Alerte compromission SI prestataire biomédical | H29: Bonjour, Nous vous contactons car nous avons constaté des potentiels accès suspects à des données de nos comptes clients en date du 6 janvier. Nos équipes sont pleinement mobilisées sur les investigations. Pour l'heure nous n'avons pas de raison de penser que des accès de maintenance aient pu être compromis. Néanmoins dans un souci de transparence, nous souhaitions vous tenir informés de cette situation et nous vous tiendrons au courant des résultats de nos investigations. | I29: E-mail
B30: ✅ | C30: T1-27 | D30: Structurant | E30: Médecin | F30: CCD CHU | G30: ="Problème DPI : "&Applicatifs!$B$4&" inaccessible" -> Problème DPI : CrossWay inaccessible | H30: =Applicatifs!$B$4&" c'est une catastrophe depuis ce matin, ça rame beaucoup, un coup il s'ouvre, un coup il ne s'ouvre pas…" -> CrossWay c'est une catastrophe depuis ce matin, ça rame beaucoup, un coup il s'ouvre, un coup il ne s'ouvre pas… | I30: Appel
B31: ✅ | C31: T1-28 | D31: Structurant | E31: Cadre de santé | F31: CCOPS CHU | G31: Problème remontée PACS | H31: Je ne comprends, pas les résultats ne remontent pas dans le DPI alors que le labo m'a dit que les résultats étaient envoyés depuis 1 heure ! | I31: Appel
B32: ✅ | C32: T1-29 | D32: Saturant | E32: Chef de service des urgences | F32: CCD CHU | G32: Plainte de l'accueil des urgences qui ne reçoivent pas les résultats du laboratoire | H32: C'est l'accueil des urgences qui vous rappelle, nous n'avons pas les résultats du laboratoire donc c'est assez problématique. Nous nous retrouvons surchargés par les différents problèmes depuis ce matin, il faut à tout prix nous donner des explications et directives. Nous n'arrivons pas à joindre le laboratoire. | I32: Appel
B33: ✅ | C33: T1-30 | D33: Saturant | E33: Cadre de santé | F33: CCOPS CHU | G33: Impression non-stop de test d'encre | H33: Bonjour, j'ai voulu imprimer le calendrier des gardes administratives en trois exemplaires, mais l'imprimante continue à imprimer des feuilles avec des tests d'encre. J'ai du faire une fausse manipulation. Je l'ai débranchée et ça continue. Vous pouvez passez la voir quand vous avez un moment ? Parce que je ne sais pas comment l'arrêter autrement. | I33: Appel
B34: ✅ | C34: T1-31 | D34: Structurant | E34: ADVENS (PRIS) | F34: CCOPS CHOR | G34: Remontée d'alerte CHOR | H34: Bonjour, nous vous remontons une alerte concernant la création de comptes administrateurs et d'élévations de privilège qui semblent coincider avec l'incident en cours au CHU. Les serveurs et postes du CHOR ne sont pas compromis et aucune trace d'exfiltration ou de chiffrement pour le moment. Nous surveillons et continuons d'investiguer. | I34: Appel
B35: ✅ | C35: T1-32 | D35: Saturant | E35: Chargée de communication | F35: CCOPS CHU | G35: Email de phishing déjoué par un agent vigilant | H35: Bonjour, j'ai reçu cet email en pièce-jointe, je pense qu'il s'agit d'une tentative de phishing, mieux vaut prévenir les autres ! Bonne journée, | I35: E-mail
B36: ✅ | C36: T1-33 | D36: Saturant | E36: Chargée de communication | F36: CCOPS CHOR | G36: Email de phishing déjoué par un agent vigilant | H36: Bonjour, j'ai reçu cet email en pièce-jointe, je pense qu'il s'agit d'une tentative de phishing, mieux vaut prévenir les autres ! Bonne journée, | I36: E-mail
B37: ✅ | C37: T1-34 | D37: Saturant | E37: Chef de service cardiologie | F37: CCD CHU | G37: Chirurgien du service de chirurgie cardiaque et vasculaire ne parvient pas à ouvrir son fichier pour accéder au programme opératoire de la semaine | H37: Bonjour, j'essaye depuis un quart d'heure d'ouvrir le fichier pour accéder au programme opératoire. Pourriez-vous m'aider à résoudre le problème ? J'ai pourtant une bonne connexion. En attendant, il me semble qu'une IDE édite le progamme opératoire tous les jours sur support papier. Je vais essayer de retrouver qui c'est. | I37: Appel
B38: ✅ | C38: T1-35 | D38: Structurant | E38: Chef de service réanimation | F38: CCD CHU | G38: Problème en réanimation sur Ré@ssist (logiciel réa) | H38: Bonjour les équipes de réanimation m'ont contacté : apparement le logiciel Ré@ssist n'est pas accessible, ils ne peuvent plus mettre à jour les données des patients, ils passent en mode dégradé, mais nous avons des patients critiques pour qui nous ne pouvons pas nous permettre de perdre même momentanément des données essentielles à la prise en charge. | I38: Appel
B39: ✅ | C39: T1-36 | D39: Structurant | E39: Cadre de santé | F39: CCD CHU | G39: Dysfonctionnement Chauffage Ventilation Clim (CVC) | H39: Bonjour, la climatisation ne fonctionne plus, vous avez prévu d'envoyer des techniciens ? | I39: Appel
B40: ✅ | C40: T1-37 | D40: Saturant | E40: Responsable RH | F40: CCOPS CHU | G40: Fichier .txt qui apparaît de manière incontrolable | H40: Bonsoir, j'ai un bug avec le PC de la pharmacie, au niveau de la zone de préparation. J'ai un document qui n'arrête pas de surgir, même si je le ferme. Est-ce que je peux redémarrer le PC ? | I40: Appel
B41: ✅ | C41: T1-38 | D41: Saturant | E41: Cadre de santé | F41: CCD CHU | G41: Plainte de plusieurs services qui ne reçoivent pas les résultats du laboratoire | H41: C'est le service X qui vous appelle, nous n'avons pas les résultats du laboratoire donc c'est assez problématique, nous nous retrouvons surchargés par les différents problèmes. Il faut à tout prix nous donner des explications et directives. Nous n'arrivons pas à joindre le labo. | I41: Appel
...

Sheet ancien chrono
A2: Etat | B2: N° | C2: Horaire | D2: Type de stimuli | E2: Personnage | F2: Destinataire | G2: Objet | H2: Corps | I2: Personnage | J2: Modalité
A3: Tango 1
B4: 2 | D4: Structurant | G4: Dysfonctionnement des pneumatiques | H4: Bonjour, j'ai l'impression qu'il y a un dysfonctionnement avec les pneumatiques, plusieurs services se sont plaints de ne pas avoir les résultats du laboratoire. | I4: Equipe Technique | J4: Appel
B5: 3 | D5: Structurant | G5: Manque de personnel | H5: Bonjour, Il nous manque du personnel aujourd'hui. Nous ne serons pas en mesure d'assurer les transferts de patients... Les véhicules sont immobilisés. | I5: Responsable brancardage | J5: SMS
B6: 4 | D6: Structurant | G6: ="Dysfonctionnement "&Applicatifs!$B$5&" (Urgences)" -> Dysfonctionnement Pastel (Urgences) | H6: ="Bonjour, on constate sur le site un gros dysfonctionnement de "&Applicatifs!$B$5&" au niveau de l'accueil des urgences. Le logiciel tourne au ralenti et il y a beaucoup de personnes qui arrivent depuis ce matin, il y a de plus en plus d'attente…" -> Bonjour, on constate sur le site un gros dysfonctionnement de Pastel au niveau de l'accueil des urgences. Le logiciel tourne au ralenti et il y a beaucoup de personnes qui arrivent depuis ce matin, il y a de plus en plus d'attente… | I6: Accueil des urgences | J6: Appel
B7: 5 | D7: Structurant | G7: ="Dysfonctionnement "&Applicatifs!$B$5&" (Urgences)" -> Dysfonctionnement Pastel (Urgences) | H7: ="Bonjour, j'ai été contacté par X qui m'a dit qu'une fois de plus il y a de gros ralentissements sur "&Applicatifs!$B$5&" à l'accueil des urgences. X me demande ce qu'ils doivent faire. Merci." -> Bonjour, j'ai été contacté par X qui m'a dit qu'une fois de plus il y a de gros ralentissements sur Pastel à l'accueil des urgences. X me demande ce qu'ils doivent faire. Merci. | I7: Cadre des admissions | J7: Appel
B8: 6 | D8: Structurant | G8: ="Dysfonctionnement "&Applicatifs!$B$5&" (Urgences)" -> Dysfonctionnement Pastel (Urgences) | H8: ="Bonjour, je vous contacte car l'accueil des urgences commence à être saturé. On a des dysfonctionnements sur les postes informatiques, notamment des gros ralentissements de "&Applicatifs!$B$5&". Cela prend 3x plus de temps de créer les dossiers patients…" -> Bonjour, je vous contacte car l'accueil des urgences commence à être saturé. On a des dysfonctionnements sur les postes informatiques, notamment des gros ralentissements de Pastel. Cela prend 3x plus de temps de créer les dossiers patients… | I8: Accueil des urgences | J8: Appel
B9: 7 | D9: Structurant | G9: ="Dysfonctionnement "&Applicatifs!$B$5&" (Urgences)" -> Dysfonctionnement Pastel (Urgences) | H9: ="Bonjour, je suis cadre aux urgences. L'accueil des urgences nous ont dit qu'ils ont un problème informatique sur "&Applicatifs!$B$5&". Ça commence à être saturé et on a du mal à travailler. Vous savez quand le problème sera résolu ?" -> Bonjour, je suis cadre aux urgences. L'accueil des urgences nous ont dit qu'ils ont un problème informatique sur Pastel. Ça commence à être saturé et on a du mal à travailler. Vous savez quand le problème sera résolu ? | I9: Service des urgences | J9: Appel
B10: 8 | D10: Structurant | G10: ="Panne "&Applicatifs!$B$6&" (Laboratoire)" -> Panne INLOG (Laboratoire) | H10: ="Bonjour, il semblerait qu'il y ait une panne au niveau du laboratoire de biologie. "&Applicatifs!$B$6&" est en panne. On doit se déplacer pour avoir les résultats, c'est très long et on a beaucoup de mal à tenir le rythme." -> Bonjour, il semblerait qu'il y ait une panne au niveau du laboratoire de biologie. INLOG est en panne. On doit se déplacer pour avoir les résultats, c'est très long et on a beaucoup de mal à tenir le rythme. | I10: Service au choix | J10: Appel
B11: 9 | D11: Structurant | G11: Plainte de l'accueil des urgences qui ne reçoivent pas les résultats du laboratoire | H11: C'est l'accueil des urgences qui vous rappelle, nous n'avons pas les résultats du laboratoire donc c'est assez problématique. Nous nous retrouvons surchargés par les différents problèmes depuis ce matin, il faut à tout prix nous donner des explications et directives. Nous n'arrivons pas à joindre le laboratoire. | I11: Accueil des urgences | J11: Appel
B12: 10 | D12: Structurant | G12: Sous-effectif à l’hôpital | H12: Bonjour, Il nous manque du personnel ce matin. Nous avons tenté de contacter l'agence d'interim' mais ils ne repondent pas... Est-ce qu'on attend l'arrivée des cadres ? On essaie en parallèle de se réorganiser en interne pour assurer la continuité des soins mais nous ne sommes pas sûrs que ce soit possible. | I12: Service de cardiologie | J12: Appel
B13: 11 | D13: Structurant | G13: Appel stressé d’un soignant | H13: Bonjour, C'est l'heure de la relève, il manque du personnel, nous ne pouvons plus acceuillir les patients... Il me faut une place dès que possible ! En plus, l'armoire à pharmacie est capricieuse un coup elle s'ouvre un coup elle ne veut pas s'ouvrir... | I13: USIC | J13: Appel
B14: 13 | D14: Structurant | G14: ="Problème "&Applicatifs!$B$9&" (Gestion des repas)" -> Problème Logiciel de gestion des repas (Gestion des repas) | H14: ="Bonjour, il semblerait qu'il y ait un gros problème avec "&Applicatifs!$B$9&" ici, on n'arrive pas à se connecter et on ne peut pas servir les repas. Vous savez ce qu'il se passe ? Ça sera réparé dans combien de temps ?" -> Bonjour, il semblerait qu'il y ait un gros problème avec Logiciel de gestion des repas ici, on n'arrive pas à se connecter et on ne peut pas servir les repas. Vous savez ce qu'il se passe ? Ça sera réparé dans combien de temps ? | I14: Service de psychiatrie | J14: Appel
B15: 14 | D15: Structurant | G15: ="Problème "&Applicatifs!$B$9&" (Gestion des repas)" -> Problème Logiciel de gestion des repas (Gestion des repas) | H15: ="Bonjour, cela fait plus de 2h que nous attendons les repas, on vient d'enchaîner 4 accouchements en parallèle, comment vous dire que là ce n'est pas possible de continuer à travailler comme ça. Vous êtes sûrs qu'il n'y a pas un problème avec "&Applicatifs!$B$9&" ?" -> Bonjour, cela fait plus de 2h que nous attendons les repas, on vient d'enchaîner 4 accouchements en parallèle, comment vous dire que là ce n'est pas possible de continuer à travailler comme ça. Vous êtes sûrs qu'il n'y a pas un problème avec Logiciel de gestion des repas ? | I15: Service maternité | J15: Appel
B16: 15 | D16: Structurant | G16: ="Problème "&Applicatifs!$B$9&" (Gestion des repas)" -> Problème Logiciel de gestion des repas (Gestion des repas) | H16: Bonjour, c'est la médecine interne, est-ce que c'est la grève aujourd'hui ? Aucun repas n'est arrivé, il se passe quelque chose dont nous ne sommes pas au courant ? | I16: Service médecine interne | J16: Appel
B17: 16 | D17: Structurant | G17: ="Problème "&Applicatifs!$B$9&" (Gestion des repas)" -> Problème Logiciel de gestion des repas (Gestion des repas) | H17: ="Nous n'arrivons pas à accéder à "&Applicatifs!$B$9&", que faisons nous ? On doit servir les petits déjeuners !" -> Nous n'arrivons pas à accéder à Logiciel de gestion des repas, que faisons nous ? On doit servir les petits déjeuners ! | I17: Service de gériatrie | J17: Appel
B18: 17 | D18: Structurant | G18: ="Panne "&Applicatifs!$B$6&" (Laboratoire)" -> Panne INLOG (Laboratoire) | H18: ="Avez-vous du nouveau concernant les problèmes avec "&Applicatifs!$B$6&" ? C'est très problématique, avez-vous des infos svp ? Quand est-ce que ça sera réglé ?" -> Avez-vous du nouveau concernant les problèmes avec INLOG ? C'est très problématique, avez-vous des infos svp ? Quand est-ce que ça sera réglé ? | I18: Service au choix | J18: Appel
B19: 18 | D19: Structurant | G19: ="Dysfonctionnement "&Applicatifs!$B$10&" (Prescription)" -> Dysfonctionnement Logipren (Prescription) | H19: Improviser | I19: Service neonatalité | J19: Appel
B20: 19 | D20: Structurant | G20: L'administrateur de garde informe le DSI | H20: ="Bonjour, j'aimerais bien joindre le DSI pour lui faire un rapport sur les différentes informations que l'on m'a remonté : Dysfonctionnements de "&Applicatifs!$B$5&" à l'accueil des urgences, "&Applicatifs!$B$6&" hors service au laboratoire, "&Applicatifs!$B$9&" qui ne fonctionne plus…" -> Bonjour, j'aimerais bien joindre le DSI pour lui faire un rapport sur les différentes informations que l'on m'a remonté : Dysfonctionnements de Pastel à l'accueil des urgences, INLOG hors service au laboratoire, Logiciel de gestion des repas qui ne fonctionne plus… | I20: Administrateur de garde | J20: Appel
B21: 20 | D21: Structurant | G21: Appel des équipes de la DSI vers le DSI pour informer des difficultés | H21: Bonjour, on nous a remonté quelques pannes sur des logiciels,et le réseau est saturé depuis cette nuit. Ca doit générer des lenteurs. On ne comprends pas ce qu'il se passe pour le moment. | I21: Equipe DSI | J21: Appel
B22: 21 | D22: Structurant | G22: Appel de la cadre qui commence à être saturée de problématiques | H22: Bonjour, on me fait remonter des problèmes de toute part, je n'arrive plus à suivre et à tout faire remonter. Mon téléphone n'arrête pas de sonner et je n'ai pas le temps d'écouter ou de lire les messages qu'on me laisse.... C'est vraiment la folie aujourd'hui y'a rien qui va !!! | I22: Cadre de santé | J22: Appel
B23: 22 | D23: Structurant | G23: Ralentissement des distributeurs de linge | H23: Bonjour, service de médecine interne, nous avons du mal à récupérer le linge, les distributeurs sont très lents. Nous en avons besoin impérativement. | I23: Service médecine interne | J23: Appel
B24: 23 | D24: Structurant | G24: Accident sur l'autoroute empêche des paramédicaux d'arriver à l'heure | H24: Bonjour, je vous contacte, car j'ai plusieurs infirmiers et aides-soignants, qui m'ont contacté pour me dire qu'ils sont coincés sur l'autoroute. Apparement, il y a eu un accident grave, et ils ne savent pas exactement dans combien de temps, ils arriveront à l'hôpital.. ils m'ont assuré qu'ils nous tiendront au courant | I24: Cadre de santé | J24: Appel
B25: 24 | D25: Structurant | G25: Manque de personnel suite à accident et retards | H25: Bonjour, je vous recontacte car nos équipes aimeraient savoir quand ils pourront rentrer chez eux... Certains ont des problèmatiques de garde d'enfants et ne peuvent pas rester plus pour combler les retards, je ne sais pas quoi leur répondre. | I25: Cadre de santé | J25: Appel
B26: 25 | D26: Structurant | G26: Le logiciel des repas ne fonctionne plus | H26: Bonjour, je vous rappele pour remonter un dysfonctionnement. Les cuisines ne peuvent plus éditer les repas et aucun services ne peut distribuer les repas c'est très embêtant… | I26: Responsable technique du site | J26: Appel
B27: 26 | D27: Structurant | G27: ="Panne "&Applicatifs!$B$11&" (Transport des patients)" -> Panne Logiciel de transport des patients (Transport des patients) | H27: ="Bonjour, je n'arrive plus à commander un transport via "&Applicatifs!$B$11&". J'ai des patients qui doivent passer des scanners d'urgence ce matin, quelle est la procédure ? J'appelle directement le responsable des brancardiers ?" -> Bonjour, je n'arrive plus à commander un transport via Logiciel de transport des patients. J'ai des patients qui doivent passer des scanners d'urgence ce matin, quelle est la procédure ? J'appelle directement le responsable des brancardiers ? | I27: Service au choix | J27: Appel
B28: 27 | D28: Structurant | G28: Une mise à jour de sécurité s’est lancée sur les postes informatiques | H28: Bonjour, Une mise à jour s'est lancée sur les postes... Nous ne pourrons pas les utiliser pendant une dizaine de minutes. | I28: Accueil des urgences | J28: Appel
B29: 28 | D29: Structurant | G29: Hypothèse de piratage service gastro | H29: Bonjour, c'est le médecin coordinateur du service gastro, je pense que le poste a été piraté, il n'y a plus rien qui répond. Avez vous une procédure prévue pour ce type de cas, je ne sais absolument pas quoi faire et ni à qui m'adresser, je vous avoue être un peu perdu, j'aurais besoin d'aide. | I29: Service gastro | J29: Appel
B30: 29 | D30: Structurant | G30: ="Bug de "&Applicatifs!$B$12&" (Gestion des plannings)" -> Bug de Logiciel de gestion des plannings (Gestion des plannings) | H30: ="Bonjour, c'est X qui vous contacte, on m'a informé qu'en plus de "&Applicatifs!$B$5&" il y a un bug sur "&Applicatifs!$B$12&". On n'a plus aucune visibilité sur les plannings, il y a une page blanche qui s'affiche sans aucun contenu, est-ce que c'est normal ?" -> Bonjour, c'est X qui vous contacte, on m'a informé qu'en plus de Pastel il y a un bug sur Logiciel de gestion des plannings. On n'a plus aucune visibilité sur les plannings, il y a une page blanche qui s'affiche sans aucun contenu, est-ce que c'est normal ? | I30: Accueil des urgences | J30: Appel
B31: 30 | D31: Structurant | G31: Le DSI demande l'appui de l'ANSSI ou du CERT Santé | H31: Bonjour, nous observons des flux étranges et massifs, on ne sait pas encore d'où ça vient mais c'est très inquiétant. La bande passante a augmenté très fortement depuis cette nuit. Est-ce qu'on peut avoir l'appui de l'ANSSI ou du CERT Santé ? | I31: DSI Territoire - service infrastructure | J31: Appel
B32: 31 | D32: Structurant | G32: ="Bug de "&Applicatifs!$B$12&" (Gestion des plannings)" -> Bug de Logiciel de gestion des plannings (Gestion des plannings) | H32: ="Il y a des bugs sur "&Applicatifs!$B$12&", il semblerait que des créneaux soient apparus disponibles sans l'être. Par conséquent nous avons un grand nombre de rendez-vous qui se chevauchent et on ne peut même plus visualiser le planning de la journée sur certains postes." -> Il y a des bugs sur Logiciel de gestion des plannings, il semblerait que des créneaux soient apparus disponibles sans l'être. Par conséquent nous avons un grand nombre de rendez-vous qui se chevauchent et on ne peut même plus visualiser le planning de la journée sur certains postes. | I32: Accueil de l'hopital | J32: Appel
B33: 32 | D33: Structurant | G33: Clé USB en cause ? | H33: Nous avons une clé USB qu'on s'est transmise ce matin entre nous aux urgences, et depuis il y a beaucoup de problèmes je pense que c'est cette clé USB qui est source de problème | I33: Accueil des urgences | J33: Appel
B34: 33 | D34: Structurant | G34: Problème de garde d'enfants des employés | H34: Bonjour, je cherche à joindre Monsieur X, son enfant est à l'infirmerie et attend d'être récupé, il faudrait venir à l'école. | I34: Divers | J34: Appel
B35: 34 | D35: Structurant | G35: Panne ascenseur | H35: Bonjour nous avons une panne d'ascenseur, nous souhaitons rapidement régler le problème mais nous n'arrivons pas à identifier pour l'instant le problème et nous ne savons pas combien de temps cela prendra pour réparer.. | I35: Divers | J35: Appel
B36: 35 | D36: Structurant | G36: Fugue d'un patient | H36: Bonjour, un patient est introuvable depuis plus d'une heure. Cela nous préoccupe beaucoup, il est particulièrement instable. | I36: Service de psychiatrie | J36: Appel
B37: 36 | D37: Structurant | G37: Démarchage équipement médical | H37: Bonjour, C'est l'entreprise Distrimed qui vous contacte, nous sommes spécialisés dans la vente de matériel médical, nous aimerions vous infromer qu'en ce moment nous avons de superbes promotions sur les éléctrocardiographes avec des offres à partir de 589 euros. N'hesitez pas à directement consulter notre site internet également. | I37: Entreprise Distrimed | J37: Appel
B38: 37 | D38: Structurant | G38: Cadre inquiet à propos des informations qui fuitent sur les problèmes informatiques | H38: Bonjour X, je suis cadre aux urgences, je me permets de vous contacter directement car j'ai un patient ce matin aux urgences qui est journaliste TF1, et comme depuis ce matin il a pu entendre qu'on rencontre des problèmes informatiques, il arrête pas de me poser des question ainsi qu'aux autres urgentistes. Je crains qu'il transmette de fausses informations ou que cela soit divulgué | I38: Service des urgences | J38: Appel
B39: 38 | D39: Structurant | G39: Responsable d’un service en congé | H39: Bonjour, nous avons une opération très importante de programmée aujourd'hui, elle ne peut pas être déprogrammée au service X mais le responsable de ce service est en congé, Nous attendons vos consignes | I39: Service de chirurgie pédiatrique | J39: Appel
B40: 39 | D40: Structurant | G40: Personne influente arrivée aux urgences - que faire ? | H40: C'est les urgences, nous avons X qui vient d'être admis aux urgences, il a fait un AVC, faut à tout prix faire quelque chose, les rumeurs ciruclent vite, nous avons pleins de patients qui viennent nous poser la question, la ligne téléphonique est débordée, c'est l'affolement total. qu'est ce qu'on doit faire ? pourrions nous avoir du renfort quelque chose avant que cela ne devienne incontroable ? | I40: Service des urgences | J40: Appel
B41: 40 | D41: Structurant | G41: Identification de fichiers chiffrés | H41: Bonjour, je viens d'analyser les serveurs des applications en panne, il y a de nombreux fichiers avec l'extension .xyz, et ils sont illisibles. Savez-vous ce qu'il se passe ? | I41: Equipe DSI | J41: Appel
...

Sheet Applicatifs
F1: Listes
F2: Modalité | G2: Type d'inject | H2: Destinataire | I2: Personnages
A3: Type d'applicatif | B3: Nom du logiciel | C3: Présence | D3: Commentaire | F3: Appel | G3: Structurant | H3: CCD CHU | I3: Technicien informatique
A4: DPI (Général) | B4: CrossWay | C4: Oui | F4: SMS | G4: Saturant | H4: CCOPS CHU | I4: Infirmière
A5: GAM (Urgences) | B5: Pastel | C5: Oui | F5: E-mail | H5: ARS | I5: Médecin
A6: SGL (Système de Gestion du Laboratoire) | B6: INLOG | C6: Oui | F6: A l'oral par le coach | H6: Préfecture | I6: Cadre de santé
A7: PACS (Imagerie) | B7: PACS | C7: Oui | H7: CCD CHOR | I7: Secrétaire médicale
A8: Armoires informatisées | B8: Armoires informatisées | C8: Oui | H8: CCOPS CHOR | I8: Chef de service des urgences
A9: Logiciel de gestion des repas | B9: Logiciel de gestion des repas | C9: Oui | H9: CCD GHER | I9: Responsable laboratoire
A10: Logiciel de prescription | B10: Logipren | C10: Oui | H10: CCOPS GHER | I10: Responsable imagerie
A11: Logiciel de transport des patients | B11: Logiciel de transport des patients | C11: Oui | H11: CC Biomédicale CHU Sud | I11: Chef de service réanimation
A12: Logiciel de gestion des plannings | B12: Logiciel de gestion des plannings | C12: Oui | I12: Chef de service cardiologie
A13: Logiciel de gestion des stocks (Pharmacie) | B13: Pharma® | C13: Oui | I13: Responsable pharmacie
A14: Logiciel de surveillance des patients (Général) | B14: Logiciel de surveillance des patients (Général) | C14: Oui | I14: Responsable maternité
A15: Logiciel de gestion de la température (Laboratoire) | B15: Logiciel de gestion de la température (Laboratoire) | C15: Oui | I15: Chirurgien
A16: Logiciel de suivi des chimiothérapies (Oncologie) | B16: Chimio | C16: Oui | I16: Psychiatrie
A17: Logiciel de gestion des salles de bloc (Urgences) | B17: HM Bloc (Hopital Manager) | C17: Oui | I17: Accueil
I18: Stérilisation
A19: Autres (Santé) | B19: Présence | C19: Commentaire | I19: Oncologie
A20: Pneumatique ? | B20: Oui | I20: Responsable RH
A21: Distributeur de linge ? | B21: Oui | I21: Responsable service batimentaire
I22: Membre d'un syndicat
A23: Autres (SI) | B23: Commentaire | C23: Corps | I23: Chargée de communication du CHU
A24: Réseau bâtimentaire ? | C24: Bonjour, les badges ne fonctionnent plus, on ne peut plus ouvrir les portes des bâtiments, les équipes ne peuvent plus entrer dans les batîments. Il y a aussi des portes qui ne se verrouillent plus et des patients qui circulent librement. Il faut trouver une solution rapidement ! | G24: ❌ | H24: ✅ | I24: Service juridique
A25: Réseau téléphonique IP ? | C25: Bonjour, sans téléphonie IP nous sommes sollicités car personne ne sait comment se joindre. C'est la panique partout là ! | I25: ANSSI
I26: CERT Santé
I27: ADVENS (PRIS)
I28: Officier CODIS 974
I29: Médecin syndicaliste du CHU Docteur Genou
I30: Permanence du cabinet du ministre de l'intérieur
I31: CORRUSS
I32: SAMU
I33: Cabinet du Premier ministre
I34: ZINFOS 974
I35: Centre pénitentier de Saint-Denis - Directeur de la prison
I36: Journaliste
I37: EFS
... I53: Prestataire biomédical - BioCom

Sheet Liste
A1: Liste
A2: Oui
A3: Non
